<?xml version="1.0"?>
<robot name="line_follower_robot">

  <!-- Base Link -->
  <link name="base_link">
    <visual>
      <geometry>
        <box size="0.2 0.1 0.05"/>
      </geometry>
      <material name="Gazebo/Orange"/>
    </visual>
    <collision>
      <geometry>
        <box size="0.2 0.1 0.05"/>
      </geometry>
    </collision>
    <inertial>
      <mass value="1.0"/>
      <inertia>
        <ixx value="0.001"/>
        <iyy value="0.001"/>
        <izz value="0.001"/>
        <ixy value="0.0"/>
        <ixz value="0.0"/>
        <iyz value="0.0"/>
      </inertia>
    </inertial>
  </link>

  <!-- Left Wheel -->
  <link name="wheel_left">
    <visual>
      <geometry>
        <cylinder length="0.02" radius="0.02"/>
      </geometry>
      <material name="Gazebo/Orange"/>
    </visual>
    <collision>
      <geometry>
        <cylinder length="0.02" radius="0.02"/>
      </geometry>
    </collision>
    <inertial>
      <mass value="0.1"/>
      <inertia>
        <ixx value="0.0001"/>
        <iyy value="0.0001"/>
        <izz value="0.0001"/>
        <ixy value="0.0"/>
        <ixz value="0.0"/>
        <iyz value="0.0"/>
      </inertia>
    </inertial>
  </link>
  <joint name="wheel_left_joint" type="continuous">
    <parent link="base_link"/>
    <child link="wheel_left"/>
    <origin xyz="-0.1 -0.05 0.02" rpy="0 0 0"/>
  </joint>

  <!-- Right Wheel -->
  <link name="wheel_right">
    <visual>
      <geometry>
        <cylinder length="0.02" radius="0.02"/>
      </geometry>
      <material name="Gazebo/Orange"/>
    </visual>
    <collision>
      <geometry>
        <cylinder length="0.02" radius="0.02"/>
      </geometry>
    </collision>
    <inertial>
      <mass value="0.1"/>
      <inertia>
        <ixx value="0.0001"/>
        <iyy value="0.0001"/>
        <izz value="0.0001"/>
        <ixy value="0.0"/>
        <ixz value="0.0"/>
        <iyz value="0.0"/>
      </inertia>
    </inertial>
  </link>
  <joint name="wheel_right_joint" type="continuous">
    <parent link="base_link"/>
    <child link="wheel_right"/>
    <origin xyz="-0.1 0.05 0.02" rpy="0 0 0"/>
  </joint>

  <!-- Line Sensor -->
  <link name="line_sensor">
    <visual>
      <geometry>
        <box size="0.05 0.02 0.02"/>
      </geometry>
      <material name="Gazebo/Orange"/>
    </visual>
    <collision>
      <geometry>
        <box size="0.05 0.02 0.02"/>
      </geometry>
    </collision>
    <inertial>
      <mass value="0.05"/>
      <inertia>
        <ixx value="0.00005"/>
        <iyy value="0.00005"/>
        <izz value="0.00005"/>
        <ixy value="0.0"/>
        <ixz value="0.0"/>
        <iyz value="0.0"/>
      </inertia>
    </inertial>
  </link>
  <joint name="sensor_joint" type="fixed">
    <parent link="base_link"/>
    <child link="line_sensor"/>
    <origin xyz="0.1 0 0.02" rpy="0 0 0"/>
    <gazebo>
      <preserveFixedJoint>true</preserveFixedJoint>
    </gazebo>
  </joint>

</robot>
