<?xml version="1.0" ?>
<sdf version="1.6">
  <model name="line_follower_robot">
    <!-- Static property -->
    <static>false</static>

    <!-- Base Link -->
    <link name="base_link">
      <!-- Visual for the base -->
      <visual name="base_visual">
        <geometry>
          <box>
            <size>0.2 0.1 0.05</size> <!-- Length, width, height -->
          </box>
        </geometry>
        <material>
          <script>
            <uri>file://media/materials/scripts/gazebo.material</uri>
            <name>Gazebo/Orange</name>
          </script>
        </material>
      </visual>

      <!-- Collision for the base -->
      <collision name="base_collision">
        <geometry>
          <box>
            <size>0.2 0.1 0.05</size>
          </box>
        </geometry>
      </collision>

      <!-- Inertial properties -->
      <inertial>
        <mass>1.0</mass>
        <inertia>
          <ixx>0.001</ixx>
          <iyy>0.001</iyy>
          <izz>0.001</izz>
          <ixy>0.0</ixy>
          <ixz>0.0</ixz>
          <iyz>0.0</iyz>
        </inertia>
      </inertial>
    </link>

    <!-- Left Wheel -->
    <link name="wheel_left">
      <visual name="left_wheel_visual">
        <geometry>
          <cylinder>
            <radius>0.02</radius>
            <length>0.01</length>
          </cylinder>
        </geometry>
        <material>
          <script>
            <uri>file://media/materials/scripts/gazebo.material</uri>
            <name>Gazebo/Black</name>
          </script>
        </material>
      </visual>
      <collision name="left_wheel_collision">
        <geometry>
          <cylinder>
            <radius>0.02</radius>
            <length>0.01</length>
          </cylinder>
        </geometry>
      </collision>
      <inertial>
        <mass>0.1</mass>
        <inertia>
          <ixx>0.0001</ixx>
          <iyy>0.0001</iyy>
          <izz>0.0001</izz>
          <ixy>0.0</ixy>
          <ixz>0.0</ixz>
          <iyz>0.0</iyz>
        </inertia>
      </inertial>
    </link>

    <!-- Right Wheel -->
    <link name="wheel_right">
      <visual name="right_wheel_visual">
        <geometry>
          <cylinder>
            <radius>0.02</radius>
            <length>0.01</length>
          </cylinder>
        </geometry>
        <material>
          <script>
            <uri>file://media/materials/scripts/gazebo.material</uri>
            <name>Gazebo/Black</name>
          </script>
        </material>
      </visual>
      <collision name="right_wheel_collision">
        <geometry>
          <cylinder>
            <radius>0.02</radius>
            <length>0.01</length>
          </cylinder>
        </geometry>
      </collision>
      <inertial>
        <mass>0.1</mass>
        <inertia>
          <ixx>0.0001</ixx>
          <iyy>0.0001</iyy>
          <izz>0.0001</izz>
          <ixy>0.0</ixy>
          <ixz>0.0</ixz>
          <iyz>0.0</iyz>
        </inertia>
      </inertial>
    </link>

    <!-- Line Sensor -->
    <link name="line_sensor">
      <visual name="sensor_visual">
        <geometry>
          <box>
            <size>0.05 0.02 0.02</size>
          </box>
        </geometry>
        <material>
          <script>
            <uri>file://media/materials/scripts/gazebo.material</uri>
            <name>Gazebo/Gray</name>
          </script>
        </material>
      </visual>
      <collision name="sensor_collision">
        <geometry>
          <box>
            <size>0.05 0.02 0.02</size>
          </box>
        </geometry>
      </collision>
      <inertial>
        <mass>0.05</mass>
        <inertia>
          <ixx>0.00005</ixx>
          <iyy>0.00005</iyy>
          <izz>0.00005</izz>
          <ixy>0.0</ixy>
          <ixz>0.0</ixz>
          <iyz>0.0</iyz>
        </inertia>
      </inertial>
    </link>

    <!-- Joints -->
    <joint name="left_wheel_joint" type="revolute">
      <parent>base_link</parent>
      <child>wheel_left</child>
      <axis>
        <xyz>0 1 0</xyz>
        <limit>
          <lower>-1.0</lower>
          <upper>1.0</upper>
        </limit>
      </axis>
    </joint>

    <joint name="right_wheel_joint" type="revolute">
      <parent>base_link</parent>
      <child>wheel_right</child>
      <axis>
        <xyz>0 1 0</xyz>
        <limit>
          <lower>-1.0</lower>
          <upper>1.0</upper>
        </limit>
      </axis>
    </joint>

    <joint name="sensor_joint" type="fixed">
      <parent>base_link</parent>
      <child>line_sensor</child>
    </joint>
  </model>
</sdf>
